# 제너레이터와 async/await

## 1. 제너레이터란?

ES6에서 도입된 제너레이터는 코드 블록의 실행을 일시 중지했다가 필요한 시점에 재개할 수 있는 특수한 함수다. 제너레이터와 일반 함수의 차이는 다음과 같다.

1. 제너레이터 함수는 함수 호출자에게 함수 실행의 제어권을 양도할 수 있다.
   - 일반 함수를 호출하면 제어권이 함수에게 넘어가고 함수 코드를 일괄 실행한다.
2. 제너레이터 함수는 함수 호출자와 상태를 주고받을 수 있다.
3. 제너레이터 함수를 호출하면 제너레이터 객체를 반환한다.

다음과 같이 `function*` 키워드로 선언할 수 있다. 화살표 함수로는 정의할 수 없다.

```js
function* genDecFunc() {
  yield 1;
}

const obj = {
  *genObjMethod() {
    yield 1;
  },
};
```

## 2. async/await

제너레이터를 사용하여 비동기 처리를 동기처럼 구현할 수 있지만 코드가 장황해지고 가독성도 나빠졌다. 이를 극복하기 위해 ES8에서 async/await가 도입되었다.

async/await는 프로미스 기반으로 동작한다. async/await는 프로미스의 후속 처리 메서드에 콜백을 전달해서 후속 처리할 필요없이 프로미스가 처리 결과를 반환하도록 구현할 수 있다.

### 2.1 async 함수

await 키워드는 반드시 async 함수 내부에서 사용해야 한다. async 함수는 언제나 프로미스를 반환한다. 프로미스를 반환하지 않더라도 암묵적으로 반환값을 resolve 하는 프로미스를 반환한다.

```js
async function foo(n) {
  return n;
}

foo(1).then((v) => console.log(v));

const baz = async (n) => {
  return n;
};

baz(2).then((v) => console.log(v));
```

### 2.2 await 키워드

await 키워드는 프로미스가 settled 상태가 될 때까지 대기하다가 settled 상태가 되면 프로미스가 resolve한 처리 결과를 반환한다. await은 반드시 프로미스 앞에서 사용해야 한다.
await 키워드는 다음 실행을 일시 중지시켰다가 프로미스가 settled 상태가 되면 다시 재개한다.

모든 프로미스에 await 키워드를 사용하는 것은 주의해야 한다. 다음 예제의 foo 함수는 종료될 때까지 6초가 소요된다. 그런데 foo 함수는 수행하는 3개의 비동기 처리가 서로 연관없이 개별적으로 수행되는 비동기 처리이므로 순차적으로 처리할 필요가 없다. 이때는 `Promise.all`로 병렬 처리하는 것이 좋다.

```js
async function foo() {
  const a = await new Promise((resolve) => setTimeout(() => resolve(1), 3000));
  const b = await new Promise((resolve) => setTimeout(() => resolve(2), 2000));
  const c = await new Promise((resolve) => setTimeout(() => resolve(3), 1000));
  console.log([a, b, c]); // [1, 2, 3]
}

foo();
```

만약 앞선 비동기 처리 결과를 가지고 다음 비동기 처리를 수행해야 할 경우는 await을 사용할 수 밖에 없다.

### 2.2 에러 처리

비동기 처리를 위한 콜백 패턴의 단점 중 가장 심각한 것은 에러 처리가 곤란하다는 것이다. `try...catch`로 에러를 캐치할 수 없다. 하지만, async/await에서 에러 처리는 `try...catch`문을 사용할 수 있다.

```js
const foo = async () => {
  try {
    const wrongUrl = "https://wrong.url";

    const response = await fetch(wrongUrl);
    const data = await response.json();
    console.log(data);
  } catch (err) {
    console.error(err);
  }
};

foo();
```

위 예제의 foo 함수의 catch 문은 HTTP 통신에서 발생한 네트워크 에러뿐 아니라 try 코드 블록 내에서 발생한 모든 에러를 캐치할 수 있다.

async 함수 내에서 catch 문을 사용해서 에러 처리를 하지 않으면 async 함수는 발생한 에러를 reject하는 프로미스를 반환한다.

```js
const foo = async () => {
  const wrongUrl = "https://wrong.url";

  const response = await fetch(wrongUrl);
  const data = await response.json();
  return data;
};

foo().then(console.log).catch(console.error); // TypeError: Failed to fetch
```
